<?xml version="1.0"?>
<robot name="slam_bot" xmlns:xacro="http://ros.org/wiki/xacro">

  <!-- Define robot constants -->
  <xacro:property name="base_width"  value="0.150"/>
  <xacro:property name="base_length" value="0.250"/>
  <xacro:property name="base_height" value="0.050"/>
  <xacro:property name="base_mass"   value="1.500"/>

  <xacro:property name="wheel_radius" value="0.050"/>
  <xacro:property name="wheel_width"  value="0.045"/>
  <xacro:property name="wheel_ygap"   value="0.025"/>
  <xacro:property name="wheel_zoff"   value="0.010"/>
  <xacro:property name="wheel_xoff"   value="0.085"/>
  <xacro:property name="wheel_mass"   value="0.100"/>

  <xacro:property name="lidar_radius" value="0.0350"/>
  <xacro:property name="lidar_width"  value="0.0700"/>
  <xacro:property name="lidar_mass"   value="0.2000"/>

  <xacro:property name="tower_width"  value="0.090"/>
  <xacro:property name="tower_length" value="0.130"/>
  <xacro:property name="tower_height" value="0.050"/>
  <xacro:property name="tower_mass"   value="0.200"/>

  <xacro:property name="rasp_width"  value="0.105"/>
  <xacro:property name="rasp_length" value="0.095"/>
  <xacro:property name="rasp_height" value="0.040"/>
  <xacro:property name="rasp_mass"   value="0.100"/> 

  <xacro:property name="camera_width"  value="0.020"/>
  <xacro:property name="camera_length" value="0.020"/>
  <xacro:property name="camera_height" value="0.020"/>
  <xacro:property name="camera_mass"   value="0.100"/>
  
  <!-- Define some commonly used intertial properties  -->
  <xacro:macro name="box_inertia" params="m w h d">
    <inertial>
      <origin xyz="0 0 0" rpy="${pi/2} 0 ${pi/2}"/>      
      <mass value="${m}"/>
      <inertia ixx="${(m/12) * (h*h + d*d)}" ixy="0.0" ixz="0.0" iyy="${(m/12) * (w*w + d*d)}" iyz="0.0" izz="${(m/12) * (w*w + h*h)}"/>
    </inertial>
  </xacro:macro>

  <xacro:macro name="cylinder_inertia" params="m r h">
    <inertial>
      <origin xyz="0 0 0" rpy="${pi/2} 0 0" />      
      <mass value="${m}"/>
      <inertia ixx="${(m/12) * (3*r*r + h*h)}" ixy = "0" ixz = "0" iyy="${(m/12) * (3*r*r + h*h)}" iyz = "0" izz="${(m/2) * (r*r)}"/> 
    </inertial>
  </xacro:macro>
  
  <!-- Robot Base -->
  <link name="base_link">
    <visual>
      <geometry>
        <box size="${base_length} ${base_width} ${base_height}"/>
      </geometry>
      <material name="Dark Grey">
        <color rgba="0.3 0.3 0.3 1.0"/>
      </material>
    </visual>

    <collision>
      <geometry>
        <box size="${base_length} ${base_width} ${base_height}"/>
      </geometry>
    </collision>

    <xacro:box_inertia m="${base_mass}" w="${base_width}" d="${base_length}" h="${base_height}"/>
  </link>
  
   <!-- Robot Footprint -->
  <link name="base_footprint">
    <xacro:box_inertia m="0" w="0" d="0" h="0"/>
  </link>

  <joint name="base_joint" type="fixed">
    <parent link="base_link"/>
    <child  link="base_footprint"/>
    <origin xyz="0 0 ${-(wheel_radius+wheel_zoff)}" rpy="0 0 0"/>
  </joint>
  
  <!-- Wheels -->
  <xacro:macro name="wheel" params="prefix x_reflect y_reflect">
    <link name="${prefix}_link">
      <visual>
        <origin xyz="0 0 0" rpy="0 0 0"/>
        <geometry>
            <mesh filename="file:///home/guen/slam_bot/src/slam_bot/meshes/mecanum.dae" scale="0.325 0.325 0.325"/>
        </geometry>
      </visual>

      <collision>
        <origin xyz="0 0 0" rpy="${pi/2} 0 0"/> 
        <geometry>
          <cylinder radius="${wheel_radius}" length="${wheel_width}"/>
        </geometry>
      </collision>

      <xacro:cylinder_inertia m="${wheel_mass}" r="${wheel_radius}" h="${wheel_width}"/>
    </link>

    <joint name="${prefix}_joint" type="continuous">
      <parent link="base_link"/>
      <child  link="${prefix}_link"/>
      <origin xyz="${x_reflect*wheel_xoff} ${y_reflect*(base_width/2+wheel_ygap)} ${-wheel_zoff}" rpy="0 0 0"/>
      <axis xyz="0 1 0"/>
    </joint>

  </xacro:macro>

  <xacro:wheel prefix="wheel_front_left"  x_reflect="1"  y_reflect="1"  />
  <xacro:wheel prefix="wheel_front_right" x_reflect="1"  y_reflect="-1" />
  <xacro:wheel prefix="wheel_back_left"   x_reflect="-1" y_reflect="1"  />
  <xacro:wheel prefix="wheel_back_right"  x_reflect="-1" y_reflect="-1" />
  
  <!-- Raspberry -->
  <link name="rasp_link">
    <visual>
      <geometry>
        <box size="${rasp_length} ${rasp_width} ${rasp_height}"/>
      </geometry>
      <material name="Dark Green">
        <color rgba="0 0.4 0 1"/>
      </material>
    </visual>
    
    <collision>
      <geometry>
        <box size="${rasp_length} ${rasp_width} ${rasp_height}"/>
      </geometry>
    </collision>
      
    <xacro:box_inertia m="${rasp_mass}" w="${rasp_width}" d="${rasp_length}" h="${rasp_height}"/>
  </link>
    
  <joint name="rasp_joint" type="fixed">
    <parent link="base_link"/>
    <child  link="rasp_link"/>
    <origin xyz="0.06 0 ${base_height/2 + rasp_height/2}"/>
  </joint>
  
  <!-- Tower -->
  <link name="tower_link">
    <visual>
      <geometry>
        <box size="${tower_length} ${tower_width} ${tower_height}"/>
      </geometry>
      <material name="Dark Grey">
        <color rgba="0.4 0.4 0.4 1"/>
      </material>
    </visual>
    
    <collision>
      <geometry>
        <box size="${tower_length} ${tower_width} ${tower_height}"/>
      </geometry>
    </collision>
      
    <xacro:box_inertia m="${tower_mass}" w="${tower_width}" d="${tower_length}" h="${tower_height}"/>
  </link>
    
  <joint name="tower_joint" type="fixed">
    <parent link="base_link"/>
    <child  link="tower_link"/>
    <origin xyz="-0.06 0 ${base_height/2 + tower_height/2}"/>
  </joint>
  
  <!-- Lidar -->
  <link name="lidar_link">
    <visual>
      <origin xyz="0 0 0" rpy="0 0 0"/>
      <geometry>
         <cylinder radius="${lidar_radius}" length="${lidar_width}"/>
      </geometry>
        <material name="Dark Grey">
          <color rgba="0.3 0.3 0.3 1"/>
        </material>
    </visual>
    <collision>
      <origin xyz="0 0 0" rpy="0 0 0"/>
      <geometry>
         <cylinder radius="${lidar_radius}" length="${lidar_width}"/>
      </geometry>
    </collision>
    <xacro:cylinder_inertia m="${lidar_mass}" r="${lidar_radius}" h="${lidar_width}"/>
  </link>

  <joint name="lidar_joint" type="fixed">
    <parent link="base_link"/>
    <child  link="lidar_link"/>
    <origin xyz="-0.06 0 ${base_height/2 + tower_height + lidar_width/2}" rpy="0 0 0"/>
  </joint>
  
  <!-- Camera -->
  <link name="camera_link">
    <visual>
      <geometry>
        <box size="${camera_length} ${camera_width} ${camera_height}"/>
      </geometry>
      <material name="Red">
        <color rgba="1 0 0 1"/>
      </material>
    </visual>
    
    <collision>
      <geometry>
        <box size="${camera_length} ${camera_width} ${camera_height}"/>
      </geometry>
    </collision>
      
    <xacro:box_inertia m="${camera_mass}" w="${camera_width}" d="${camera_length}" h="${camera_height}"/>
  </link>
    
  <joint name="camera_joint" type="fixed">
    <parent link="base_link"/>
    <child  link="camera_link"/>
    <origin xyz="0.09 0 0.075"/>
  </joint>
  
  <!-- Camer Optica -->
  <link name="camera_link_optical"/>

  <joint name="camera_optical_joint" type="fixed">
    <parent link="camera_link"/>
    <child link="camera_link_optical"/>
    <origin xyz="0 0 0" rpy="${-pi/2} 0 ${-pi/2}"/>
  </joint>

  <!-- IMU -->
  <link name="imu_link"/>
    
  <joint name="imu_joint" type="fixed">
    <parent link="base_link"/>
    <child  link="imu_link"/>
    <origin xyz="0 0 0"/>
  </joint>

</robot>
